Workbook

Sheet Todos
A1: CONTROLN | B1: STATE | C1: GENDER | D1: HV1 | E1: IC1 | F1: IC4 | G1: HVP1 | H1: IC5 | I1: POBC1 | J1: POBC2 | K1: IC2 | L1: IC3 | M1: AVGGIFT | N1: TCODE | O1: DOB | P1: DOMAIN | Q1: TARGET_D | R1: AGE | S1: NEIGHBORHOOD_TYPE | T1: GENDER_CLEAN | U1: STATE_CLEAN | V1: IC5_CLEAN
A2: 44060 | B2: FL | C2: M | D2: AAA896 | E2: 392 | F2: 520 | G2: 7 | H2: 21975 | I2: 6 | J2: 16 | K2: 430 | L2: 466 | M2: 28 | N2: =IFERROR(VLOOKUP(A2,vlookup_table!$A:$G,2,FALSE),"") -> 1 | O2: =IFERROR(VLOOKUP(A2,vlookup_table!$A:$G,4,FALSE),"") -> 1901 | P2: =IFERROR(VLOOKUP(A2,vlookup_table!$A:$G,5,FALSE),"") -> C2 | Q2: =IFERROR(VLOOKUP(A2,vlookup_table!$A:$G,7,FALSE),"") -> 100 | R2: =IF(O2="","",97-INT(O2/100)) -> 78 | S2: {=IF(P2="","",_xlfn.SWITCH(LEFT(P2,1),"C","Ciudad","T","Pueblo","R","Rural","S","Suburbano","U","Urbano",""))} -> Ciudad | T2: =IF(C2="","",IF(OR(UPPER(C2)="M",UPPER(C2)="MALE"),"M",IF(OR(UPPER(C2)="F",UPPER(C2)="FEMALE",UPPER(C2)="FEAMALE"),"F",C2))) -> M | U2: =IF(OR(UPPER(B2)="CALIFORNIA",UPPER(B2)="CALI"),"CA",B2) -> FL | V2: =SUBSTITUTE(H2,"@","") -> 21975
A3: 96093 | B3: IL | C3: M | D3: 537 | E3: 365 | F3: 473 | G3: 0 | H3: 19387 | I3: 1 | J3: 89 | K3: 415 | L3: 410 | M3: 5.6666667 | N3: =IFERROR(VLOOKUP(A3,vlookup_table!$A:$G,2,FALSE),"") -> 0 | O3: =IFERROR(VLOOKUP(A3,vlookup_table!$A:$G,4,FALSE),"") -> 0 | P3: =IFERROR(VLOOKUP(A3,vlookup_table!$A:$G,5,FALSE),"") -> T2 | Q3: =IFERROR(VLOOKUP(A3,vlookup_table!$A:$G,7,FALSE),"") -> 7 | R3: =IF(O3="","",97-INT(O3/100)) -> 97 | S3: {=IF(P3="","",_xlfn.SWITCH(LEFT(P3,1),"C","Ciudad","T","Pueblo","R","Rural","S","Suburbano","U","Urbano",""))} -> Pueblo | T3: =IF(C3="","",IF(OR(UPPER(C3)="M",UPPER(C3)="MALE"),"M",IF(OR(UPPER(C3)="F",UPPER(C3)="FEMALE",UPPER(C3)="FEAMALE"),"F",C3))) -> M | U3: =IF(OR(UPPER(B3)="CALIFORNIA",UPPER(B3)="CALI"),"CA",B3) -> IL | V3: =SUBSTITUTE(H3,"@","") -> 19387
A4: 43333 | B4: FL | C4: F | D4: 725 | E4: 301 | F4: 436 | G4: 3 | H4: 18837 | I4: 11 | J4: 17 | K4: 340 | L4: 361 | M4: 4.1111111 | N4: =IFERROR(VLOOKUP(A4,vlookup_table!$A:$G,2,FALSE),"") -> 0 | O4: =IFERROR(VLOOKUP(A4,vlookup_table!$A:$G,4,FALSE),"") -> 2501 | P4: =IFERROR(VLOOKUP(A4,vlookup_table!$A:$G,5,FALSE),"") -> C2 | Q4: =IFERROR(VLOOKUP(A4,vlookup_table!$A:$G,7,FALSE),"") -> 5 | R4: =IF(O4="","",97-INT(O4/100)) -> 72 | S4: {=IF(P4="","",_xlfn.SWITCH(LEFT(P4,1),"C","Ciudad","T","Pueblo","R","Rural","S","Suburbano","U","Urbano",""))} -> Ciudad | T4: =IF(C4="","",IF(OR(UPPER(C4)="M",UPPER(C4)="MALE"),"M",IF(OR(UPPER(C4)="F",UPPER(C4)="FEMALE",UPPER(C4)="FEAMALE"),"F",C4))) -> F | U4: =IF(OR(UPPER(B4)="CALIFORNIA",UPPER(B4)="CALI"),"CA",B4) -> FL | V4: =SUBSTITUTE(H4,"@","") -> 18837
A5: 21885 | B5: NC | C5: M | D5: AAA1095 | E5: 401 | F5: 413 | G5: 7 | H5: 14014 | I5: 1 | J5: 74 | K5: 407 | L5: 399 | M5: 27.277778 | N5: =IFERROR(VLOOKUP(A5,vlookup_table!$A:$G,2,FALSE),"") -> 0 | O5: =IFERROR(VLOOKUP(A5,vlookup_table!$A:$G,4,FALSE),"") -> 2208 | P5: =IFERROR(VLOOKUP(A5,vlookup_table!$A:$G,5,FALSE),"") -> T2 | Q5: =IFERROR(VLOOKUP(A5,vlookup_table!$A:$G,7,FALSE),"") -> 38 | R5: =IF(O5="","",97-INT(O5/100)) -> 75 | S5: {=IF(P5="","",_xlfn.SWITCH(LEFT(P5,1),"C","Ciudad","T","Pueblo","R","Rural","S","Suburbano","U","Urbano",""))} -> Pueblo | T5: =IF(C5="","",IF(OR(UPPER(C5)="M",UPPER(C5)="MALE"),"M",IF(OR(UPPER(C5)="F",UPPER(C5)="FEMALE",UPPER(C5)="FEAMALE"),"F",C5))) -> M | U5: =IF(OR(UPPER(B5)="CALIFORNIA",UPPER(B5)="CALI"),"CA",B5) -> NC | V5: =SUBSTITUTE(H5,"@","") -> 14014
A6: 190108 | B6: FL | C6: F | D6: 995 | E6: 252 | F6: 348 | G6: 0 | H6: 17991 | I6: 5 | J6: 6 | K6: 280 | L6: 316 | M6: 6 | N6: =IFERROR(VLOOKUP(A6,vlookup_table!$A:$G,2,FALSE),"") -> 28 | O6: =IFERROR(VLOOKUP(A6,vlookup_table!$A:$G,4,FALSE),"") -> 0 | P6: =IFERROR(VLOOKUP(A6,vlookup_table!$A:$G,5,FALSE),"") -> C2 | Q6: =IFERROR(VLOOKUP(A6,vlookup_table!$A:$G,7,FALSE),"") -> 5 | R6: =IF(O6="","",97-INT(O6/100)) -> 97 | S6: {=IF(P6="","",_xlfn.SWITCH(LEFT(P6,1),"C","Ciudad","T","Pueblo","R","Rural","S","Suburbano","U","Urbano",""))} -> Ciudad | T6: =IF(C6="","",IF(OR(UPPER(C6)="M",UPPER(C6)="MALE"),"M",IF(OR(UPPER(C6)="F",UPPER(C6)="FEMALE",UPPER(C6)="FEAMALE"),"F",C6))) -> F | U6: =IF(OR(UPPER(B6)="CALIFORNIA",UPPER(B6)="CALI"),"CA",B6) -> FL | V6: =SUBSTITUTE(H6,"@","") -> 17991
A7: 100640 | B7: IL | C7: M | D7: 764 | E7: 457 | F7: 501 | G7: 1 | H7: 16022 | I7: 2 | J7: 75 | K7: 477 | L7: 480 | M7: 25.571429 | N7: =IFERROR(VLOOKUP(A7,vlookup_table!$A:$G,2,FALSE),"") -> 1 | O7: =IFERROR(VLOOKUP(A7,vlookup_table!$A:$G,4,FALSE),"") -> 6104 | P7: =IFERROR(VLOOKUP(A7,vlookup_table!$A:$G,5,FALSE),"") -> S2 | Q7: =IFERROR(VLOOKUP(A7,vlookup_table!$A:$G,7,FALSE),"") -> 30 | R7: =IF(O7="","",97-INT(O7/100)) -> 36 | S7: {=IF(P7="","",_xlfn.SWITCH(LEFT(P7,1),"C","Ciudad","T","Pueblo","R","Rural","S","Suburbano","U","Urbano",""))} -> Suburbano | T7: =IF(C7="","",IF(OR(UPPER(C7)="M",UPPER(C7)="MALE"),"M",IF(OR(UPPER(C7)="F",UPPER(C7)="FEMALE",UPPER(C7)="FEAMALE"),"F",C7))) -> M | U7: =IF(OR(UPPER(B7)="CALIFORNIA",UPPER(B7)="CALI"),"CA",B7) -> IL | V7: =SUBSTITUTE(H7,"@","") -> 16022
A8: 18581 | B8: NC | C8: female | D8: 775 | E8: 318 | F8: 419 | G8: 5 | H8: 13491 | I8: 0 | J8: 73 | K8: 364 | L8: 380 | M8: 4.625 | N8: =IFERROR(VLOOKUP(A8,vlookup_table!$A:$G,2,FALSE),"") -> 0 | O8: =IFERROR(VLOOKUP(A8,vlookup_table!$A:$G,4,FALSE),"") -> 4407 | P8: =IFERROR(VLOOKUP(A8,vlookup_table!$A:$G,5,FALSE),"") -> R2 | Q8: =IFERROR(VLOOKUP(A8,vlookup_table!$A:$G,7,FALSE),"") -> 12 | R8: =IF(O8="","",97-INT(O8/100)) -> 53 | S8: {=IF(P8="","",_xlfn.SWITCH(LEFT(P8,1),"C","Ciudad","T","Pueblo","R","Rural","S","Suburbano","U","Urbano",""))} -> Rural | T8: =IF(C8="","",IF(OR(UPPER(C8)="M",UPPER(C8)="MALE"),"M",IF(OR(UPPER(C8)="F",UPPER(C8)="FEMALE",UPPER(C8)="FEAMALE"),"F",C8))) -> F | U8: =IF(OR(UPPER(B8)="CALIFORNIA",UPPER(B8)="CALI"),"CA",B8) -> NC | V8: =SUBSTITUTE(H8,"@","") -> 13491
A9: 119038 | B9: TX | C9: M | D9: 890 | E9: 519 | F9: 560 | G9: 0 | H9: 17872 | I9: 2 | J9: 46 | K9: 525 | L9: 551 | M9: 6.175 | N9: =IFERROR(VLOOKUP(A9,vlookup_table!$A:$G,2,FALSE),"") -> 1002 | O9: =IFERROR(VLOOKUP(A9,vlookup_table!$A:$G,4,FALSE),"") -> 0 | P9: =IFERROR(VLOOKUP(A9,vlookup_table!$A:$G,5,FALSE),"") -> C1 | Q9: =IFERROR(VLOOKUP(A9,vlookup_table!$A:$G,7,FALSE),"") -> 7 | R9: =IF(O9="","",97-INT(O9/100)) -> 97 | S9: {=IF(P9="","",_xlfn.SWITCH(LEFT(P9,1),"C","Ciudad","T","Pueblo","R","Rural","S","Suburbano","U","Urbano",""))} -> Ciudad | T9: =IF(C9="","",IF(OR(UPPER(C9)="M",UPPER(C9)="MALE"),"M",IF(OR(UPPER(C9)="F",UPPER(C9)="FEMALE",UPPER(C9)="FEAMALE"),"F",C9))) -> M | U9: =IF(OR(UPPER(B9)="CALIFORNIA",UPPER(B9)="CALI"),"CA",B9) -> TX | V9: =SUBSTITUTE(H9,"@","") -> 17872
A10: 173223 | B10: CA | C10: F | E10: 184 | F10: 250 | G10: 0 | H10: 8708 | I10: 2 | J10: 63 | K10: 206 | L10: 235 | M10: 8.8181818 | N10: =IFERROR(VLOOKUP(A10,vlookup_table!$A:$G,2,FALSE),"") -> 0 | O10: =IFERROR(VLOOKUP(A10,vlookup_table!$A:$G,4,FALSE),"") -> 1801 | P10: =IFERROR(VLOOKUP(A10,vlookup_table!$A:$G,5,FALSE),"") -> T2 | Q10: =IFERROR(VLOOKUP(A10,vlookup_table!$A:$G,7,FALSE),"") -> 10 | R10: =IF(O10="","",97-INT(O10/100)) -> 79 | S10: {=IF(P10="","",_xlfn.SWITCH(LEFT(P10,1),"C","Ciudad","T","Pueblo","R","Rural","S","Suburbano","U","Urbano",""))} -> Pueblo | T10: =IF(C10="","",IF(OR(UPPER(C10)="M",UPPER(C10)="MALE"),"M",IF(OR(UPPER(C10)="F",UPPER(C10)="FEMALE",UPPER(C10)="FEAMALE"),"F",C10))) -> F | U10: =IF(OR(UPPER(B10)="CALIFORNIA",UPPER(B10)="CALI"),"CA",B10) -> CA | V10: =SUBSTITUTE(H10,"@","") -> 8708
A11: 157988 | B11: CA | C11: F | D11: AAA2294 | E11: 593 | F11: 617 | G11: 61 | H11: 17838 | I11: 7 | J11: 62 | L11: 619 | M11: 6.6666667 | N11: =IFERROR(VLOOKUP(A11,vlookup_table!$A:$G,2,FALSE),"") -> 28 | O11: =IFERROR(VLOOKUP(A11,vlookup_table!$A:$G,4,FALSE),"") -> 0 | P11: =IFERROR(VLOOKUP(A11,vlookup_table!$A:$G,5,FALSE),"") -> S1 | Q11: =IFERROR(VLOOKUP(A11,vlookup_table!$A:$G,7,FALSE),"") -> 10 | R11: =IF(O11="","",97-INT(O11/100)) -> 97 | S11: {=IF(P11="","",_xlfn.SWITCH(LEFT(P11,1),"C","Ciudad","T","Pueblo","R","Rural","S","Suburbano","U","Urbano",""))} -> Suburbano | T11: =IF(C11="","",IF(OR(UPPER(C11)="M",UPPER(C11)="MALE"),"M",IF(OR(UPPER(C11)="F",UPPER(C11)="FEMALE",UPPER(C11)="FEAMALE"),"F",C11))) -> F | U11: =IF(OR(UPPER(B11)="CALIFORNIA",UPPER(B11)="CALI"),"CA",B11) -> CA | V11: =SUBSTITUTE(H11,"@","") -> 17838
A12: 141720 | B12: NV | C12: F | D12: 1569 | E12: 673 | F12: 781 | G12: 22 | H12: 25775 | I12: 3 | J12: 44 | K12: 672 | L12: 785 | M12: 13 | N12: =IFERROR(VLOOKUP(A12,vlookup_table!$A:$G,2,FALSE),"") -> 28 | O12: =IFERROR(VLOOKUP(A12,vlookup_table!$A:$G,4,FALSE),"") -> 5401 | P12: =IFERROR(VLOOKUP(A12,vlookup_table!$A:$G,5,FALSE),"") -> T1 | Q12: =IFERROR(VLOOKUP(A12,vlookup_table!$A:$G,7,FALSE),"") -> 5 | R12: =IF(O12="","",97-INT(O12/100)) -> 43 | S12: {=IF(P12="","",_xlfn.SWITCH(LEFT(P12,1),"C","Ciudad","T","Pueblo","R","Rural","S","Suburbano","U","Urbano",""))} -> Pueblo | T12: =IF(C12="","",IF(OR(UPPER(C12)="M",UPPER(C12)="MALE"),"M",IF(OR(UPPER(C12)="F",UPPER(C12)="FEMALE",UPPER(C12)="FEAMALE"),"F",C12))) -> F | U12: =IF(OR(UPPER(B12)="CALIFORNIA",UPPER(B12)="CALI"),"CA",B12) -> NV | V12: =SUBSTITUTE(H12,"@","") -> 25775
A13: 186272 | B13: CA | C13: F | D13: 3515 | E13: 521 | F13: 588 | G13: 97 | H13: 20068 | I13: 11 | J13: 54 | K13: 565 | L13: 549 | M13: 8.64 | N13: =IFERROR(VLOOKUP(A13,vlookup_table!$A:$G,2,FALSE),"") -> 2 | O13: =IFERROR(VLOOKUP(A13,vlookup_table!$A:$G,4,FALSE),"") -> 3401 | P13: =IFERROR(VLOOKUP(A13,vlookup_table!$A:$G,5,FALSE),"") -> U1 | Q13: =IFERROR(VLOOKUP(A13,vlookup_table!$A:$G,7,FALSE),"") -> 10 | R13: =IF(O13="","",97-INT(O13/100)) -> 63 | S13: {=IF(P13="","",_xlfn.SWITCH(LEFT(P13,1),"C","Ciudad","T","Pueblo","R","Rural","S","Suburbano","U","Urbano",""))} -> Urbano | T13: =IF(C13="","",IF(OR(UPPER(C13)="M",UPPER(C13)="MALE"),"M",IF(OR(UPPER(C13)="F",UPPER(C13)="FEMALE",UPPER(C13)="FEAMALE"),"F",C13))) -> F | U13: =IF(OR(UPPER(B13)="CALIFORNIA",UPPER(B13)="CALI"),"CA",B13) -> CA | V13: =SUBSTITUTE(H13,"@","") -> 20068
A14: 154301 | B14: Cali | C14: F | D14: 1026 | E14: 459 | F14: 496 | G14: 1 | H14: 13803 | I14: 12 | J14: 52 | K14: 470 | L14: 491 | M14: 11.25 | N14: =IFERROR(VLOOKUP(A14,vlookup_table!$A:$G,2,FALSE),"") -> 2 | O14: =IFERROR(VLOOKUP(A14,vlookup_table!$A:$G,4,FALSE),"") -> 2801 | P14: =IFERROR(VLOOKUP(A14,vlookup_table!$A:$G,5,FALSE),"") -> T2 | Q14: =IFERROR(VLOOKUP(A14,vlookup_table!$A:$G,7,FALSE),"") -> 10 | R14: =IF(O14="","",97-INT(O14/100)) -> 69 | S14: {=IF(P14="","",_xlfn.SWITCH(LEFT(P14,1),"C","Ciudad","T","Pueblo","R","Rural","S","Suburbano","U","Urbano",""))} -> Pueblo | T14: =IF(C14="","",IF(OR(UPPER(C14)="M",UPPER(C14)="MALE"),"M",IF(OR(UPPER(C14)="F",UPPER(C14)="FEMALE",UPPER(C14)="FEAMALE"),"F",C14))) -> F | U14: =IF(OR(UPPER(B14)="CALIFORNIA",UPPER(B14)="CALI"),"CA",B14) -> CA | V14: =SUBSTITUTE(H14,"@","") -> 13803
A15: 189722 | B15: AP | C15: Male | D15: 0 | E15: 0 | F15: 0 | G15: 0 | H15: 0 | I15: 0 | J15: 0 | K15: 0 | L15: 0 | M15: 5.7272727 | N15: =IFERROR(VLOOKUP(A15,vlookup_table!$A:$G,2,FALSE),"") -> 1 | O15: =IFERROR(VLOOKUP(A15,vlookup_table!$A:$G,4,FALSE),"") -> 0 | P15: =IFERROR(VLOOKUP(A15,vlookup_table!$A:$G,5,FALSE),"") -> 0 | Q15: =IFERROR(VLOOKUP(A15,vlookup_table!$A:$G,7,FALSE),"") -> 6 | R15: =IF(O15="","",97-INT(O15/100)) -> 97 | S15: {=IF(P15="","",_xlfn.SWITCH(LEFT(P15,1),"C","Ciudad","T","Pueblo","R","Rural","S","Suburbano","U","Urbano",""))} | T15: =IF(C15="","",IF(OR(UPPER(C15)="M",UPPER(C15)="MALE"),"M",IF(OR(UPPER(C15)="F",UPPER(C15)="FEMALE",UPPER(C15)="FEAMALE"),"F",C15))) -> M | U15: =IF(OR(UPPER(B15)="CALIFORNIA",UPPER(B15)="CALI"),"CA",B15) -> AP | V15: =SUBSTITUTE(H15,"@","") -> 0
A16: 188304 | B16: KS | C16: F | D16: 376 | E16: 263 | F16: 316 | G16: 0 | H16: 10755 | I16: 1 | J16: 75 | K16: 303 | L16: 287 | M16: 10.55 | N16: =IFERROR(VLOOKUP(A16,vlookup_table!$A:$G,2,FALSE),"") -> 0 | O16: =IFERROR(VLOOKUP(A16,vlookup_table!$A:$G,4,FALSE),"") -> 2405 | P16: =IFERROR(VLOOKUP(A16,vlookup_table!$A:$G,5,FALSE),"") -> T2 | Q16: =IFERROR(VLOOKUP(A16,vlookup_table!$A:$G,7,FALSE),"") -> 10 | R16: =IF(O16="","",97-INT(O16/100)) -> 73 | S16: {=IF(P16="","",_xlfn.SWITCH(LEFT(P16,1),"C","Ciudad","T","Pueblo","R","Rural","S","Suburbano","U","Urbano",""))} -> Pueblo | T16: =IF(C16="","",IF(OR(UPPER(C16)="M",UPPER(C16)="MALE"),"M",IF(OR(UPPER(C16)="F",UPPER(C16)="FEMALE",UPPER(C16)="FEAMALE"),"F",C16))) -> F | U16: =IF(OR(UPPER(B16)="CALIFORNIA",UPPER(B16)="CALI"),"CA",B16) -> KS | V16: =SUBSTITUTE(H16,"@","") -> 10755
A17: 73699 | B17: MI | D17: 890 | E17: 463 | F17: 523 | G17: 1 | H17: 9493 | I17: 5 | J17: 53 | K17: 474 | L17: 512 | M17: 11.285714 | N17: =IFERROR(VLOOKUP(A17,vlookup_table!$A:$G,2,FALSE),"") -> 1 | O17: =IFERROR(VLOOKUP(A17,vlookup_table!$A:$G,4,FALSE),"") -> 5102 | P17: =IFERROR(VLOOKUP(A17,vlookup_table!$A:$G,5,FALSE),"") -> S1 | Q17: =IFERROR(VLOOKUP(A17,vlookup_table!$A:$G,7,FALSE),"") -> 15 | R17: =IF(O17="","",97-INT(O17/100)) -> 46 | S17: {=IF(P17="","",_xlfn.SWITCH(LEFT(P17,1),"C","Ciudad","T","Pueblo","R","Rural","S","Suburbano","U","Urbano",""))} -> Suburbano | T17: =IF(C17="","",IF(OR(UPPER(C17)="M",UPPER(C17)="MALE"),"M",IF(OR(UPPER(C17)="F",UPPER(C17)="FEMALE",UPPER(C17)="FEAMALE"),"F",C17))) | U17: =IF(OR(UPPER(B17)="CALIFORNIA",UPPER(B17)="CALI"),"CA",B17) -> MI | V17: =SUBSTITUTE(H17,"@","") -> 9493
A18: 31977 | B18: FL | C18: F | D18: 1513 | E18: 521 | F18: 702 | G18: 31 | H18: 28124 | I18: 3 | J18: 24 | K18: 599 | L18: 615 | M18: 18.5 | N18: =IFERROR(VLOOKUP(A18,vlookup_table!$A:$G,2,FALSE),"") -> 2 | O18: =IFERROR(VLOOKUP(A18,vlookup_table!$A:$G,4,FALSE),"") -> 2701 | P18: =IFERROR(VLOOKUP(A18,vlookup_table!$A:$G,5,FALSE),"") -> T1 | Q18: =IFERROR(VLOOKUP(A18,vlookup_table!$A:$G,7,FALSE),"") -> 28 | R18: =IF(O18="","",97-INT(O18/100)) -> 70 | S18: {=IF(P18="","",_xlfn.SWITCH(LEFT(P18,1),"C","Ciudad","T","Pueblo","R","Rural","S","Suburbano","U","Urbano",""))} -> Pueblo | T18: =IF(C18="","",IF(OR(UPPER(C18)="M",UPPER(C18)="MALE"),"M",IF(OR(UPPER(C18)="F",UPPER(C18)="FEMALE",UPPER(C18)="FEAMALE"),"F",C18))) -> F | U18: =IF(OR(UPPER(B18)="CALIFORNIA",UPPER(B18)="CALI"),"CA",B18) -> FL | V18: =SUBSTITUTE(H18,"@","") -> 28124
A19: 44336 | B19: FL | C19: F | D19: 948 | E19: 330 | F19: 411 | G19: 4 | H19: 17728 | I19: 6 | J19: 8 | K19: 365 | L19: 368 | M19: 15 | N19: =IFERROR(VLOOKUP(A19,vlookup_table!$A:$G,2,FALSE),"") -> 0 | O19: =IFERROR(VLOOKUP(A19,vlookup_table!$A:$G,4,FALSE),"") -> 6501 | P19: =IFERROR(VLOOKUP(A19,vlookup_table!$A:$G,5,FALSE),"") -> C2 | Q19: =IFERROR(VLOOKUP(A19,vlookup_table!$A:$G,7,FALSE),"") -> 15 | R19: =IF(O19="","",97-INT(O19/100)) -> 32 | S19: {=IF(P19="","",_xlfn.SWITCH(LEFT(P19,1),"C","Ciudad","T","Pueblo","R","Rural","S","Suburbano","U","Urbano",""))} -> Ciudad | T19: =IF(C19="","",IF(OR(UPPER(C19)="M",UPPER(C19)="MALE"),"M",IF(OR(UPPER(C19)="F",UPPER(C19)="FEMALE",UPPER(C19)="FEAMALE"),"F",C19))) -> F | U19: =IF(OR(UPPER(B19)="CALIFORNIA",UPPER(B19)="CALI"),"CA",B19) -> FL | V19: =SUBSTITUTE(H19,"@","") -> 17728
A20: 127823 | B20: TX | C20: F | D20: 258 | E20: 64 | F20: 74 | G20: 0 | H20: 4236 | I20: 0 | J20: 94 | K20: 60 | L20: 93 | M20: 5.45 | N20: =IFERROR(VLOOKUP(A20,vlookup_table!$A:$G,2,FALSE),"") -> 2 | O20: =IFERROR(VLOOKUP(A20,vlookup_table!$A:$G,4,FALSE),"") -> 2301 | P20: =IFERROR(VLOOKUP(A20,vlookup_table!$A:$G,5,FALSE),"") -> C3 | Q20: =IFERROR(VLOOKUP(A20,vlookup_table!$A:$G,7,FALSE),"") -> 6 | R20: =IF(O20="","",97-INT(O20/100)) -> 74 | S20: {=IF(P20="","",_xlfn.SWITCH(LEFT(P20,1),"C","Ciudad","T","Pueblo","R","Rural","S","Suburbano","U","Urbano",""))} -> Ciudad | T20: =IF(C20="","",IF(OR(UPPER(C20)="M",UPPER(C20)="MALE"),"M",IF(OR(UPPER(C20)="F",UPPER(C20)="FEMALE",UPPER(C20)="FEAMALE"),"F",C20))) -> F | U20: =IF(OR(UPPER(B20)="CALIFORNIA",UPPER(B20)="CALI"),"CA",B20) -> TX | V20: =SUBSTITUTE(H20,"@","") -> 4236
A21: 150739 | B21: CA | C21: U | D21: 1951 | E21: 556 | F21: 625 | G21: 44 | H21: 17208 | I21: 10 | J21: 66 | K21: 578 | L21: 619 | M21: 9.6818182 | N21: =IFERROR(VLOOKUP(A21,vlookup_table!$A:$G,2,FALSE),"") -> 2 | O21: =IFERROR(VLOOKUP(A21,vlookup_table!$A:$G,4,FALSE),"") -> 5410 | P21: =IFERROR(VLOOKUP(A21,vlookup_table!$A:$G,5,FALSE),"") -> S1 | Q21: =IFERROR(VLOOKUP(A21,vlookup_table!$A:$G,7,FALSE),"") -> 12 | R21: =IF(O21="","",97-INT(O21/100)) -> 43 | S21: {=IF(P21="","",_xlfn.SWITCH(LEFT(P21,1),"C","Ciudad","T","Pueblo","R","Rural","S","Suburbano","U","Urbano",""))} -> Suburbano | T21: =IF(C21="","",IF(OR(UPPER(C21)="M",UPPER(C21)="MALE"),"M",IF(OR(UPPER(C21)="F",UPPER(C21)="FEMALE",UPPER(C21)="FEAMALE"),"F",C21))) -> U | U21: =IF(OR(UPPER(B21)="CALIFORNIA",UPPER(B21)="CALI"),"CA",B21) -> CA | V21: =SUBSTITUTE(H21,"@","") -> 17208
A22: 41384 | B22: FL | C22: F | D22: 556 | E22: 318 | G22: 0 | H22: 11779 | I22: 16 | J22: 22 | K22: 358 | L22: 320 | M22: 9.4285714 | N22: =IFERROR(VLOOKUP(A22,vlookup_table!$A:$G,2,FALSE),"") -> 28 | O22: =IFERROR(VLOOKUP(A22,vlookup_table!$A:$G,4,FALSE),"") -> 5107 | P22: =IFERROR(VLOOKUP(A22,vlookup_table!$A:$G,5,FALSE),"") -> S3 | Q22: =IFERROR(VLOOKUP(A22,vlookup_table!$A:$G,7,FALSE),"") -> 12 | R22: =IF(O22="","",97-INT(O22/100)) -> 46 | S22: {=IF(P22="","",_xlfn.SWITCH(LEFT(P22,1),"C","Ciudad","T","Pueblo","R","Rural","S","Suburbano","U","Urbano",""))} -> Suburbano | T22: =IF(C22="","",IF(OR(UPPER(C22)="M",UPPER(C22)="MALE"),"M",IF(OR(UPPER(C22)="F",UPPER(C22)="FEMALE",UPPER(C22)="FEAMALE"),"F",C22))) -> F | U22: =IF(OR(UPPER(B22)="CALIFORNIA",UPPER(B22)="CALI"),"CA",B22) -> FL | V22: =SUBSTITUTE(H22,"@","") -> 11779
A23: 114721 | B23: OK | D23: 1040 | E23: 472 | F23: 656 | G23: 0 | H23: 26962 | I23: 2 | J23: 56 | K23: 609 | L23: 579 | M23: 11.666667 | N23: =IFERROR(VLOOKUP(A23,vlookup_table!$A:$G,2,FALSE),"") -> 0 | O23: =IFERROR(VLOOKUP(A23,vlookup_table!$A:$G,4,FALSE),"") -> 0 | P23: =IFERROR(VLOOKUP(A23,vlookup_table!$A:$G,5,FALSE),"") -> C2 | Q23: =IFERROR(VLOOKUP(A23,vlookup_table!$A:$G,7,FALSE),"") -> 15 | R23: =IF(O23="","",97-INT(O23/100)) -> 97 | S23: {=IF(P23="","",_xlfn.SWITCH(LEFT(P23,1),"C","Ciudad","T","Pueblo","R","Rural","S","Suburbano","U","Urbano",""))} -> Ciudad | T23: =IF(C23="","",IF(OR(UPPER(C23)="M",UPPER(C23)="MALE"),"M",IF(OR(UPPER(C23)="F",UPPER(C23)="FEMALE",UPPER(C23)="FEAMALE"),"F",C23))) | U23: =IF(OR(UPPER(B23)="CALIFORNIA",UPPER(B23)="CALI"),"CA",B23) -> OK | V23: =SUBSTITUTE(H23,"@","") -> 26962
A24: 111795 | B24: AR | D24: 603 | E24: 208 | F24: 341 | G24: 2 | H24: 12038 | I24: 1 | J24: 70 | K24: 264 | L24: 288 | M24: 5 | N24: =IFERROR(VLOOKUP(A24,vlookup_table!$A:$G,2,FALSE),"") -> 0 | O24: =IFERROR(VLOOKUP(A24,vlookup_table!$A:$G,4,FALSE),"") -> 0 | P24: =IFERROR(VLOOKUP(A24,vlookup_table!$A:$G,5,FALSE),"") -> 0 | Q24: =IFERROR(VLOOKUP(A24,vlookup_table!$A:$G,7,FALSE),"") -> 5 | R24: =IF(O24="","",97-INT(O24/100)) -> 97 | S24: {=IF(P24="","",_xlfn.SWITCH(LEFT(P24,1),"C","Ciudad","T","Pueblo","R","Rural","S","Suburbano","U","Urbano",""))} | T24: =IF(C24="","",IF(OR(UPPER(C24)="M",UPPER(C24)="MALE"),"M",IF(OR(UPPER(C24)="F",UPPER(C24)="FEMALE",UPPER(C24)="FEAMALE"),"F",C24))) | U24: =IF(OR(UPPER(B24)="CALIFORNIA",UPPER(B24)="CALI"),"CA",B24) -> AR | V24: =SUBSTITUTE(H24,"@","") -> 12038
A25: 64480 | B25: IN | C25: F | D25: 526 | E25: 277 | F25: 370 | G25: 1 | H25: 12826 | I25: 1 | J25: 80 | K25: 336 | L25: 317 | M25: 7.1428571 | N25: =IFERROR(VLOOKUP(A25,vlookup_table!$A:$G,2,FALSE),"") -> 28 | O25: =IFERROR(VLOOKUP(A25,vlookup_table!$A:$G,4,FALSE),"") -> 0 | P25: =IFERROR(VLOOKUP(A25,vlookup_table!$A:$G,5,FALSE),"") -> T2 | Q25: =IFERROR(VLOOKUP(A25,vlookup_table!$A:$G,7,FALSE),"") -> 10 | R25: =IF(O25="","",97-INT(O25/100)) -> 97 | S25: {=IF(P25="","",_xlfn.SWITCH(LEFT(P25,1),"C","Ciudad","T","Pueblo","R","Rural","S","Suburbano","U","Urbano",""))} -> Pueblo | T25: =IF(C25="","",IF(OR(UPPER(C25)="M",UPPER(C25)="MALE"),"M",IF(OR(UPPER(C25)="F",UPPER(C25)="FEMALE",UPPER(C25)="FEAMALE"),"F",C25))) -> F | U25: =IF(OR(UPPER(B25)="CALIFORNIA",UPPER(B25)="CALI"),"CA",B25) -> IN | V25: =SUBSTITUTE(H25,"@","") -> 12826
A26: 87259 | B26: MT | C26: M | D26: 717 | E26: 302 | F26: 432 | G26: 1 | H26: 15614 | I26: 1 | J26: 53 | K26: 458 | L26: 349 | M26: 9.7 | N26: =IFERROR(VLOOKUP(A26,vlookup_table!$A:$G,2,FALSE),"") -> 2 | O26: =IFERROR(VLOOKUP(A26,vlookup_table!$A:$G,4,FALSE),"") -> 4304 | P26: =IFERROR(VLOOKUP(A26,vlookup_table!$A:$G,5,FALSE),"") -> C1 | Q26: =IFERROR(VLOOKUP(A26,vlookup_table!$A:$G,7,FALSE),"") -> 25 | R26: =IF(O26="","",97-INT(O26/100)) -> 54 | S26: {=IF(P26="","",_xlfn.SWITCH(LEFT(P26,1),"C","Ciudad","T","Pueblo","R","Rural","S","Suburbano","U","Urbano",""))} -> Ciudad | T26: =IF(C26="","",IF(OR(UPPER(C26)="M",UPPER(C26)="MALE"),"M",IF(OR(UPPER(C26)="F",UPPER(C26)="FEMALE",UPPER(C26)="FEAMALE"),"F",C26))) -> M | U26: =IF(OR(UPPER(B26)="CALIFORNIA",UPPER(B26)="CALI"),"CA",B26) -> MT | V26: =SUBSTITUTE(H26,"@","") -> 15614
A27: 115823 | B27: TX | C27: M | D27: 1011 | E27: 593 | F27: 650 | G27: 1 | H27: 17606 | I27: 5 | J27: 61 | K27: 588 | L27: 650 | M27: 6.5 | N27: =IFERROR(VLOOKUP(A27,vlookup_table!$A:$G,2,FALSE),"") -> 0 | O27: =IFERROR(VLOOKUP(A27,vlookup_table!$A:$G,4,FALSE),"") -> 0 | P27: =IFERROR(VLOOKUP(A27,vlookup_table!$A:$G,5,FALSE),"") -> S1 | Q27: =IFERROR(VLOOKUP(A27,vlookup_table!$A:$G,7,FALSE),"") -> 15 | R27: =IF(O27="","",97-INT(O27/100)) -> 97 | S27: {=IF(P27="","",_xlfn.SWITCH(LEFT(P27,1),"C","Ciudad","T","Pueblo","R","Rural","S","Suburbano","U","Urbano",""))} -> Suburbano | T27: =IF(C27="","",IF(OR(UPPER(C27)="M",UPPER(C27)="MALE"),"M",IF(OR(UPPER(C27)="F",UPPER(C27)="FEMALE",UPPER(C27)="FEAMALE"),"F",C27))) -> M | U27: =IF(OR(UPPER(B27)="CALIFORNIA",UPPER(B27)="CALI"),"CA",B27) -> TX | V27: =SUBSTITUTE(H27,"@","") -> 17606
A28: 95701 | B28: IL | C28: M | D28: 1063 | E28: 255 | F28: 317 | G28: 3 | H28: 14023 | I28: 16 | J28: 53 | K28: 260 | L28: 312 | M28: 8.3727907 | N28: =IFERROR(VLOOKUP(A28,vlookup_table!$A:$G,2,FALSE),"") -> 1 | O28: =IFERROR(VLOOKUP(A28,vlookup_table!$A:$G,4,FALSE),"") -> 4406 | P28: =IFERROR(VLOOKUP(A28,vlookup_table!$A:$G,5,FALSE),"") -> S2 | Q28: =IFERROR(VLOOKUP(A28,vlookup_table!$A:$G,7,FALSE),"") -> 5 | R28: =IF(O28="","",97-INT(O28/100)) -> 53 | S28: {=IF(P28="","",_xlfn.SWITCH(LEFT(P28,1),"C","Ciudad","T","Pueblo","R","Rural","S","Suburbano","U","Urbano",""))} -> Suburbano | T28: =IF(C28="","",IF(OR(UPPER(C28)="M",UPPER(C28)="MALE"),"M",IF(OR(UPPER(C28)="F",UPPER(C28)="FEMALE",UPPER(C28)="FEAMALE"),"F",C28))) -> M | U28: =IF(OR(UPPER(B28)="CALIFORNIA",UPPER(B28)="CALI"),"CA",B28) -> IL | V28: =SUBSTITUTE(H28,"@","") -> 14023
A29: 5172 | B29: IL | C29: M | D29: 291 | E29: 136 | F29: 212 | G29: 0 | H29: 8370 | I29: 5 | J29: 67 | K29: 168 | L29: 180 | M29: 10.611111 | N29: =IFERROR(VLOOKUP(A29,vlookup_table!$A:$G,2,FALSE),"") -> 1 | O29: =IFERROR(VLOOKUP(A29,vlookup_table!$A:$G,4,FALSE),"") -> 6105 | P29: =IFERROR(VLOOKUP(A29,vlookup_table!$A:$G,5,FALSE),"") -> R3 | Q29: =IFERROR(VLOOKUP(A29,vlookup_table!$A:$G,7,FALSE),"") -> 10 | R29: =IF(O29="","",97-INT(O29/100)) -> 36 | S29: {=IF(P29="","",_xlfn.SWITCH(LEFT(P29,1),"C","Ciudad","T","Pueblo","R","Rural","S","Suburbano","U","Urbano",""))} -> Rural | T29: =IF(C29="","",IF(OR(UPPER(C29)="M",UPPER(C29)="MALE"),"M",IF(OR(UPPER(C29)="F",UPPER(C29)="FEMALE",UPPER(C29)="FEAMALE"),"F",C29))) -> M | U29: =IF(OR(UPPER(B29)="CALIFORNIA",UPPER(B29)="CALI"),"CA",B29) -> IL | V29: =SUBSTITUTE(H29,"@","") -> 8370
A30: 152486 | B30: CA | C30: M | D30: 1538 | E30: 271 | F30: 393 | G30: 11 | H30: 15627 | I30: 5 | J30: 49 | K30: 317 | L30: 342 | M30: 5.5 | N30: =IFERROR(VLOOKUP(A30,vlookup_table!$A:$G,2,FALSE),"") -> 1 | O30: =IFERROR(VLOOKUP(A30,vlookup_table!$A:$G,4,FALSE),"") -> 2401 | P30: =IFERROR(VLOOKUP(A30,vlookup_table!$A:$G,5,FALSE),"") -> S2 | Q30: =IFERROR(VLOOKUP(A30,vlookup_table!$A:$G,7,FALSE),"") -> 5 | R30: =IF(O30="","",97-INT(O30/100)) -> 73 | S30: {=IF(P30="","",_xlfn.SWITCH(LEFT(P30,1),"C","Ciudad","T","Pueblo","R","Rural","S","Suburbano","U","Urbano",""))} -> Suburbano | T30: =IF(C30="","",IF(OR(UPPER(C30)="M",UPPER(C30)="MALE"),"M",IF(OR(UPPER(C30)="F",UPPER(C30)="FEMALE",UPPER(C30)="FEAMALE"),"F",C30))) -> M | U30: =IF(OR(UPPER(B30)="CALIFORNIA",UPPER(B30)="CALI"),"CA",B30) -> CA | V30: =SUBSTITUTE(H30,"@","") -> 15627
A31: 153880 | B31: WI | C31: F | D31: 592 | E31: 244 | F31: 392 | G31: 1 | H31: 12220 | I31: 3 | J31: 74 | K31: 341 | L31: 306 | M31: 12.5 | N31: =IFERROR(VLOOKUP(A31,vlookup_table!$A:$G,2,FALSE),"") -> 2 | O31: =IFERROR(VLOOKUP(A31,vlookup_table!$A:$G,4,FALSE),"") -> 5001 | P31: =IFERROR(VLOOKUP(A31,vlookup_table!$A:$G,5,FALSE),"") -> S1 | Q31: =IFERROR(VLOOKUP(A31,vlookup_table!$A:$G,7,FALSE),"") -> 5 | R31: =IF(O31="","",97-INT(O31/100)) -> 47 | S31: {=IF(P31="","",_xlfn.SWITCH(LEFT(P31,1),"C","Ciudad","T","Pueblo","R","Rural","S","Suburbano","U","Urbano",""))} -> Suburbano | T31: =IF(C31="","",IF(OR(UPPER(C31)="M",UPPER(C31)="MALE"),"M",IF(OR(UPPER(C31)="F",UPPER(C31)="FEMALE",UPPER(C31)="FEAMALE"),"F",C31))) -> F | U31: =IF(OR(UPPER(B31)="CALIFORNIA",UPPER(B31)="CALI"),"CA",B31) -> WI | V31: =SUBSTITUTE(H31,"@","") -> 12220
A32: 101855 | B32: MO | C32: M | D32: 871 | E32: 340 | F32: 416 | G32: 6 | H32: 15336 | I32: 0 | J32: 71 | K32: 385 | L32: 365 | M32: 7.8571429 | N32: =IFERROR(VLOOKUP(A32,vlookup_table!$A:$G,2,FALSE),"") -> 1 | O32: =IFERROR(VLOOKUP(A32,vlookup_table!$A:$G,4,FALSE),"") -> 2401 | P32: =IFERROR(VLOOKUP(A32,vlookup_table!$A:$G,5,FALSE),"") -> C2 | Q32: =IFERROR(VLOOKUP(A32,vlookup_table!$A:$G,7,FALSE),"") -> 10 | R32: =IF(O32="","",97-INT(O32/100)) -> 73 | S32: {=IF(P32="","",_xlfn.SWITCH(LEFT(P32,1),"C","Ciudad","T","Pueblo","R","Rural","S","Suburbano","U","Urbano",""))} -> Ciudad | T32: =IF(C32="","",IF(OR(UPPER(C32)="M",UPPER(C32)="MALE"),"M",IF(OR(UPPER(C32)="F",UPPER(C32)="FEMALE",UPPER(C32)="FEAMALE"),"F",C32))) -> M | U32: =IF(OR(UPPER(B32)="CALIFORNIA",UPPER(B32)="CALI"),"CA",B32) -> MO | V32: =SUBSTITUTE(H32,"@","") -> 15336
A33: 62932 | B33: IN | C33: M | D33: 403 | E33: 174 | F33: 264 | G33: 1 | H33: 9704 | I33: 0 | J33: 45 | K33: 240 | L33: 201 | M33: 8 | N33: =IFERROR(VLOOKUP(A33,vlookup_table!$A:$G,2,FALSE),"") -> 1 | O33: =IFERROR(VLOOKUP(A33,vlookup_table!$A:$G,4,FALSE),"") -> 0 | P33: =IFERROR(VLOOKUP(A33,vlookup_table!$A:$G,5,FALSE),"") -> S3 | Q33: =IFERROR(VLOOKUP(A33,vlookup_table!$A:$G,7,FALSE),"") -> 10 | R33: =IF(O33="","",97-INT(O33/100)) -> 97 | S33: {=IF(P33="","",_xlfn.SWITCH(LEFT(P33,1),"C","Ciudad","T","Pueblo","R","Rural","S","Suburbano","U","Urbano",""))} -> Suburbano | T33: =IF(C33="","",IF(OR(UPPER(C33)="M",UPPER(C33)="MALE"),"M",IF(OR(UPPER(C33)="F",UPPER(C33)="FEMALE",UPPER(C33)="FEAMALE"),"F",C33))) -> M | U33: =IF(OR(UPPER(B33)="CALIFORNIA",UPPER(B33)="CALI"),"CA",B33) -> IN | V33: =SUBSTITUTE(H33,"@","") -> 9704
A34: 125930 | B34: TX | C34: F | D34: 715 | E34: 339 | F34: 396 | G34: 1 | H34: 12617 | I34: 3 | J34: 88 | K34: 378 | L34: 371 | M34: 6 | N34: =IFERROR(VLOOKUP(A34,vlookup_table!$A:$G,2,FALSE),"") -> 0 | O34: =IFERROR(VLOOKUP(A34,vlookup_table!$A:$G,4,FALSE),"") -> 4806 | P34: =IFERROR(VLOOKUP(A34,vlookup_table!$A:$G,5,FALSE),"") -> R2 | Q34: =IFERROR(VLOOKUP(A34,vlookup_table!$A:$G,7,FALSE),"") -> 7.5 | R34: =IF(O34="","",97-INT(O34/100)) -> 49 | S34: {=IF(P34="","",_xlfn.SWITCH(LEFT(P34,1),"C","Ciudad","T","Pueblo","R","Rural","S","Suburbano","U","Urbano",""))} -> Rural | T34: =IF(C34="","",IF(OR(UPPER(C34)="M",UPPER(C34)="MALE"),"M",IF(OR(UPPER(C34)="F",UPPER(C34)="FEMALE",UPPER(C34)="FEAMALE"),"F",C34))) -> F | U34: =IF(OR(UPPER(B34)="CALIFORNIA",UPPER(B34)="CALI"),"CA",B34) -> TX | V34: =SUBSTITUTE(H34,"@","") -> 12617
A35: 173653 | B35: HI | C35: F | D35: 2346 | E35: 420 | F35: 503 | G35: 67 | H35: 14552 | I35: 5 | J35: 78 | K35: 446 | L35: 468 | M35: 15.5 | N35: =IFERROR(VLOOKUP(A35,vlookup_table!$A:$G,2,FALSE),"") -> 28 | O35: =IFERROR(VLOOKUP(A35,vlookup_table!$A:$G,4,FALSE),"") -> 2401 | P35: =IFERROR(VLOOKUP(A35,vlookup_table!$A:$G,5,FALSE),"") -> C2 | Q35: =IFERROR(VLOOKUP(A35,vlookup_table!$A:$G,7,FALSE),"") -> 21 | R35: =IF(O35="","",97-INT(O35/100)) -> 73 | S35: {=IF(P35="","",_xlfn.SWITCH(LEFT(P35,1),"C","Ciudad","T","Pueblo","R","Rural","S","Suburbano","U","Urbano",""))} -> Ciudad | T35: =IF(C35="","",IF(OR(UPPER(C35)="M",UPPER(C35)="MALE"),"M",IF(OR(UPPER(C35)="F",UPPER(C35)="FEMALE",UPPER(C35)="FEAMALE"),"F",C35))) -> F | U35: =IF(OR(UPPER(B35)="CALIFORNIA",UPPER(B35)="CALI"),"CA",B35) -> HI | V35: =SUBSTITUTE(H35,"@","") -> 14552
A36: 11011 | B36: FL | C36: M | D36: 559 | E36: 232 | F36: 269 | G36: 0 | H36: 10511 | I36: 11 | J36: 20 | K36: 270 | L36: 257 | M36: 12.611111 | N36: =IFERROR(VLOOKUP(A36,vlookup_table!$A:$G,2,FALSE),"") -> 1002 | O36: =IFERROR(VLOOKUP(A36,vlookup_table!$A:$G,4,FALSE),"") -> 2601 | P36: =IFERROR(VLOOKUP(A36,vlookup_table!$A:$G,5,FALSE),"") -> S3 | Q36: =IFERROR(VLOOKUP(A36,vlookup_table!$A:$G,7,FALSE),"") -> 20 | R36: =IF(O36="","",97-INT(O36/100)) -> 71 | S36: {=IF(P36="","",_xlfn.SWITCH(LEFT(P36,1),"C","Ciudad","T","Pueblo","R","Rural","S","Suburbano","U","Urbano",""))} -> Suburbano | T36: =IF(C36="","",IF(OR(UPPER(C36)="M",UPPER(C36)="MALE"),"M",IF(OR(UPPER(C36)="F",UPPER(C36)="FEMALE",UPPER(C36)="FEAMALE"),"F",C36))) -> M | U36: =IF(OR(UPPER(B36)="CALIFORNIA",UPPER(B36)="CALI"),"CA",B36) -> FL | V36: =SUBSTITUTE(H36,"@","") -> 10511
A37: 116894 | B37: TX | C37: M | E37: 368 | F37: 531 | G37: 5 | H37: 33797 | I37: 2 | J37: 42 | K37: 457 | L37: 450 | M37: 12.25 | N37: =IFERROR(VLOOKUP(A37,vlookup_table!$A:$G,2,FALSE),"") -> 1 | O37: =IFERROR(VLOOKUP(A37,vlookup_table!$A:$G,4,FALSE),"") -> 2201 | P37: =IFERROR(VLOOKUP(A37,vlookup_table!$A:$G,5,FALSE),"") -> U1 | Q37: =IFERROR(VLOOKUP(A37,vlookup_table!$A:$G,7,FALSE),"") -> 20 | R37: =IF(O37="","",97-INT(O37/100)) -> 75 | S37: {=IF(P37="","",_xlfn.SWITCH(LEFT(P37,1),"C","Ciudad","T","Pueblo","R","Rural","S","Suburbano","U","Urbano",""))} -> Urbano | T37: =IF(C37="","",IF(OR(UPPER(C37)="M",UPPER(C37)="MALE"),"M",IF(OR(UPPER(C37)="F",UPPER(C37)="FEMALE",UPPER(C37)="FEAMALE"),"F",C37))) -> M | U37: =IF(OR(UPPER(B37)="CALIFORNIA",UPPER(B37)="CALI"),"CA",B37) -> TX | V37: =SUBSTITUTE(H37,"@","") -> 33797
A38: 154245 | B38: CA | C38: F | D38: 596 | E38: 164 | F38: 190 | G38: 0 | H38: 5273 | I38: 23 | J38: 57 | K38: 168 | L38: 181 | M38: 16.5 | N38: =IFERROR(VLOOKUP(A38,vlookup_table!$A:$G,2,FALSE),"") -> 2 | O38: =IFERROR(VLOOKUP(A38,vlookup_table!$A:$G,4,FALSE),"") -> 4304 | P38: =IFERROR(VLOOKUP(A38,vlookup_table!$A:$G,5,FALSE),"") -> R1 | Q38: =IFERROR(VLOOKUP(A38,vlookup_table!$A:$G,7,FALSE),"") -> 15 | R38: =IF(O38="","",97-INT(O38/100)) -> 54 | S38: {=IF(P38="","",_xlfn.SWITCH(LEFT(P38,1),"C","Ciudad","T","Pueblo","R","Rural","S","Suburbano","U","Urbano",""))} -> Rural | T38: =IF(C38="","",IF(OR(UPPER(C38)="M",UPPER(C38)="MALE"),"M",IF(OR(UPPER(C38)="F",UPPER(C38)="FEMALE",UPPER(C38)="FEAMALE"),"F",C38))) -> F | U38: =IF(OR(UPPER(B38)="CALIFORNIA",UPPER(B38)="CALI"),"CA",B38) -> CA | V38: =SUBSTITUTE(H38,"@","") -> 5273
A39: 134773 | B39: UT | C39: M | D39: 706 | E39: 362 | F39: 394 | G39: 1 | H39: 10420 | I39: 1 | J39: 82 | K39: 376 | L39: 379 | M39: 15 | N39: =IFERROR(VLOOKUP(A39,vlookup_table!$A:$G,2,FALSE),"") -> 1 | O39: =IFERROR(VLOOKUP(A39,vlookup_table!$A:$G,4,FALSE),"") -> 3201 | P39: =IFERROR(VLOOKUP(A39,vlookup_table!$A:$G,5,FALSE),"") -> C3 | Q39: =IFERROR(VLOOKUP(A39,vlookup_table!$A:$G,7,FALSE),"") -> 25 | R39: =IF(O39="","",97-INT(O39/100)) -> 65 | S39: {=IF(P39="","",_xlfn.SWITCH(LEFT(P39,1),"C","Ciudad","T","Pueblo","R","Rural","S","Suburbano","U","Urbano",""))} -> Ciudad | T39: =IF(C39="","",IF(OR(UPPER(C39)="M",UPPER(C39)="MALE"),"M",IF(OR(UPPER(C39)="F",UPPER(C39)="FEMALE",UPPER(C39)="FEAMALE"),"F",C39))) -> M | U39: =IF(OR(UPPER(B39)="CALIFORNIA",UPPER(B39)="CALI"),"CA",B39) -> UT | V39: =SUBSTITUTE(H39,"@","") -> 10420
A40: 26271 | B40: GA | C40: F | D40: 878 | E40: 310 | F40: 588 | G40: 30 | H40: 22281 | I40: 4 | J40: 55 | K40: 517 | L40: 433 | M40: 10.133333 | N40: =IFERROR(VLOOKUP(A40,vlookup_table!$A:$G,2,FALSE),"") -> 28 | O40: =IFERROR(VLOOKUP(A40,vlookup_table!$A:$G,4,FALSE),"") -> 3701 | P40: =IFERROR(VLOOKUP(A40,vlookup_table!$A:$G,5,FALSE),"") -> C2 | Q40: =IFERROR(VLOOKUP(A40,vlookup_table!$A:$G,7,FALSE),"") -> 16 | R40: =IF(O40="","",97-INT(O40/100)) -> 60 | S40: {=IF(P40="","",_xlfn.SWITCH(LEFT(P40,1),"C","Ciudad","T","Pueblo","R","Rural","S","Suburbano","U","Urbano",""))} -> Ciudad | T40: =IF(C40="","",IF(OR(UPPER(C40)="M",UPPER(C40)="MALE"),"M",IF(OR(UPPER(C40)="F",UPPER(C40)="FEMALE",UPPER(C40)="FEAMALE"),"F",C40))) -> F | U40: =IF(OR(UPPER(B40)="CALIFORNIA",UPPER(B40)="CALI"),"CA",B40) -> GA | V40: =SUBSTITUTE(H40,"@","") -> 22281
...

Sheet vlookup_table
A1: CONTROLN | B1: TCODE | C1: STATE | D1: DOB | E1: DOMAIN | F1: GENDER | G1: TARGET_D
A2: 44060 | B2: 1 | C2: FL | D2: 1901 | E2: C2 | F2: M | G2: 100
A3: 96093 | B3: 0 | C3: IL | D3: 0 | E3: T2 | F3: M | G3: 7
A4: 43333 | B4: 0 | C4: FL | D4: 2501 | E4: C2 | F4: F | G4: 5
A5: 21885 | B5: 0 | C5: NC | D5: 2208 | E5: T2 | F5: M | G5: 38
A6: 190108 | B6: 28 | C6: FL | D6: 0 | E6: C2 | F6: F | G6: 5
A7: 100640 | B7: 1 | C7: IL | D7: 6104 | E7: S2 | F7: M | G7: 30
A8: 18581 | B8: 0 | C8: NC | D8: 4407 | E8: R2 | F8: F | G8: 12
A9: 119038 | B9: 1002 | C9: TX | D9: 0 | E9: C1 | F9: M | G9: 7
A10: 173223 | B10: 0 | C10: CA | D10: 1801 | E10: T2 | F10: F | G10: 10
A11: 157988 | B11: 28 | C11: CA | D11: 0 | E11: S1 | F11: F | G11: 10
A12: 141720 | B12: 28 | C12: NV | D12: 5401 | E12: T1 | F12: F | G12: 5
A13: 186272 | B13: 2 | C13: CA | D13: 3401 | E13: U1 | F13: F | G13: 10
A14: 154301 | B14: 2 | C14: CA | D14: 2801 | E14: T2 | F14: F | G14: 10
A15: 189722 | B15: 1 | C15: AP | D15: 0 | F15: M | G15: 6
A16: 188304 | B16: 0 | C16: KS | D16: 2405 | E16: T2 | F16: F | G16: 10
A17: 73699 | B17: 1 | C17: MI | D17: 5102 | E17: S1 | G17: 15
A18: 31977 | B18: 2 | C18: FL | D18: 2701 | E18: T1 | F18: F | G18: 28
A19: 44336 | B19: 0 | C19: FL | D19: 6501 | E19: C2 | F19: F | G19: 15
A20: 127823 | B20: 2 | C20: TX | D20: 2301 | E20: C3 | F20: F | G20: 6
A21: 150739 | B21: 2 | C21: CA | D21: 5410 | E21: S1 | F21: U | G21: 12
A22: 41384 | B22: 28 | C22: FL | D22: 5107 | E22: S3 | F22: F | G22: 12
A23: 114721 | B23: 0 | C23: OK | D23: 0 | E23: C2 | G23: 15
A24: 111795 | B24: 0 | C24: AR | D24: 0 | G24: 5
A25: 64480 | B25: 28 | C25: IN | D25: 0 | E25: T2 | F25: F | G25: 10
A26: 87259 | B26: 2 | C26: MT | D26: 4304 | E26: C1 | F26: M | G26: 25
A27: 115823 | B27: 0 | C27: TX | D27: 0 | E27: S1 | F27: M | G27: 15
A28: 95701 | B28: 1 | C28: IL | D28: 4406 | E28: S2 | F28: M | G28: 5
A29: 5172 | B29: 1 | C29: IL | D29: 6105 | E29: R3 | F29: M | G29: 10
A30: 152486 | B30: 1 | C30: CA | D30: 2401 | E30: S2 | F30: M | G30: 5
A31: 153880 | B31: 2 | C31: WI | D31: 5001 | E31: S1 | F31: F | G31: 5
A32: 101855 | B32: 1 | C32: MO | D32: 2401 | E32: C2 | F32: M | G32: 10
A33: 62932 | B33: 1 | C33: IN | D33: 0 | E33: S3 | F33: M | G33: 10
A34: 125930 | B34: 0 | C34: TX | D34: 4806 | E34: R2 | F34: F | G34: 7.5
A35: 173653 | B35: 28 | C35: HI | D35: 2401 | E35: C2 | F35: F | G35: 21
A36: 11011 | B36: 1002 | C36: FL | D36: 2601 | E36: S3 | F36: M | G36: 20
A37: 116894 | B37: 1 | C37: TX | D37: 2201 | E37: U1 | F37: M | G37: 20
A38: 154245 | B38: 2 | C38: CA | D38: 4304 | E38: R1 | F38: F | G38: 15
A39: 134773 | B39: 1 | C39: UT | D39: 3201 | E39: C3 | F39: M | G39: 25
A40: 26271 | B40: 28 | C40: GA | D40: 3701 | E40: C2 | F40: F | G40: 16
...

Sheet Fórmulas Lab 4
A1: Función | B1: Fórmula | C1: Resultado
A2: SUMA (Donaciones TARGET_D) | B2: =SUMA(Todos!Q:Q) | C2: =SUM(Todos!Q:Q) -> 62811
A3: PROMEDIO (AVGGIFT) | B3: =PROMEDIO(Todos!M:M) | C3: =AVERAGE(Todos!M:M) -> 11.771435
A4: CONTAR (Edades numéricas) | B4: =CONTAR(Todos!R:R) | C4: =COUNT(Todos!R:R) -> 4028
A5: CONTAR.SI (Edad > 50) | B5: =CONTAR.SI(Todos!R:R,">50") | C5: =COUNTIF(Todos!R:R,">50") -> 3170
A6: CONTAR.SI (Género = M) | B6: =CONTAR.SI(Todos!T:T,"M") | C6: =COUNTIF(Todos!T:T,"M") -> 1635
A7: MAX (Edad máxima) | B7: =MAX(Todos!R:R) | C7: =MAX(Todos!R:R) -> 97
A8: MIN (Donación mínima >0) | B8: =MIN.SI(Todos!M:M,">0") | C8: =_xlfn.MINIFS(Todos!M:M,Todos!M:M,">0") -> 2.2608696
A9: MAX (Donación máxima) | B9: =MAX(Todos!M:M) | C9: =MAX(Todos!M:M) -> 450
A10: SI (Clasificación edad fila 2) | B10: =SI(Todos!R2>65,"Mayor","Joven") | C10: =IF(Todos!R2>65,"Mayor","Joven") -> Mayor
A11: BUSCARV (TARGET_D de CONTROLN 44060) | B11: =BUSCARV(44060,vlookup_table!A:G,7,FALSO) | C11: =VLOOKUP(44060,vlookup_table!A:G,7,FALSE) -> 100
A12: CONCATENAR (Estado + Vecindario fila 2) | B12: =CONCATENAR(Todos!U2," - ",Todos!S2) | C12: =_xlfn.CONCAT(Todos!U2," - ",Todos!S2) -> FL - Ciudad
A13: HOY (Fecha actual) | B13: =HOY() | C13: =TODAY() -> 46275
A14: AHORA (Fecha y hora actual) | B14: =AHORA() | C14: =NOW() -> 46275.673
A15: REDONDEAR (AVGGIFT fila 3 a 2 dec) | B15: =REDONDEAR(Todos!M3,2) | C15: =ROUND(Todos!M3,2) -> 5.67
A17: --- ESTADÍSTICAS ADICIONALES ---
A18: CONTAR.SI (Género = F) | B18: =CONTAR.SI(Todos!T:T,"F") | C18: =COUNTIF(Todos!T:T,"F") -> 2164
A19: CONTAR.SI (Vecindario = Ciudad) | B19: =CONTAR.SI(Todos!S:S,"Ciudad") | C19: =COUNTIF(Todos!S:S,"Ciudad") -> 827
A20: PROMEDIO (Edad) | B20: =PROMEDIO(Todos!R:R) | C20: =AVERAGE(Todos!R:R) -> 69.941162
A21: CONTARA (Total registros) | B21: =CONTARA(Todos!A:A)-1 | C21: =COUNTA(Todos!A:A)-1 -> 4028
A22: SUMA (IC5 original) | B22: =SUMA(Todos!H:H) | C22: =SUM(Todos!H:H) -> 66191634
